<?xml version="1.0" ?>
<!-- =================================================================================== -->
<!-- |    This document was autogenerated by xacro from /home/qzq/catkin_ws/src/robot_description/urdf/robot.xacro | -->
<!-- |    EDITING THIS FILE BY HAND IS NOT RECOMMENDED                                 | -->
<!-- =================================================================================== -->
<robot name="robot">
    <!-- 底盘与基底关节属性 -->
    <!-- z= 车体高度 / 2 + 离地间距 - 车轮半径 -->
    <!-- z= 车体高度 / 2 + 车轮半径 -->
    <!-- 设置 base_footprint  -->
    <link name="base_footprint">
        <visual>
            <geometry>
                <sphere radius="0.001" />
            </geometry>
        </visual>
    </link>
    <!-- 底盘 -->
    <link name="car_base_link">
        <visual>
            <geometry>
                <box size="0.6 0.4 0.1" />
            </geometry>
            <origin rpy="0 0 0" xyz="0 0 0" />
            <material name="yellow">
                <color rgba="0.8 0.3 0.1 0.5" />
            </material>
        </visual>
        <collision>
            <geometry>
                <box size="0.6 0.4 0.1" />
            </geometry>
            <origin rpy="0 0 0" xyz="0 0 0" />
        </collision>
        <inertial>
            <mass value="0.1" />
            <inertia ixx="0.0030833333333333333" ixy="0" ixz="0" iyy="0.004333333333333334" iyz="0" izz="0.001416666666666667" />
            <origin xyz="0 0 0" rpy="0 0 0" />
        </inertial>
    </link>
    <!-- 基底与底盘的关节 -->
    <joint name="base_link2base_footprint" type="fixed">
        <parent link="base_footprint" />
        <child link="car_base_link" />
        <origin xyz="0 0 0.09" />
    </joint>
    <!-- 底盘颜色 -->
    <gazebo reference="base_link">
        <material>Gazebo/Yellow</material>
        <plugin name="gazebo_ros_control">
            <robotNamespace>/</robotNamespace>
        </plugin>
    </gazebo>
    <link name="left_drive">
        <visual>
            <geometry>
                <cylinder length="0.04" radius="0.06" />
            </geometry>
            <origin rpy="1.5707963 0 0" xyz="0 0 0" />
            <material name="wheel_color">
                <color rgba="0 0 0 1" />
            </material>
        </visual>
        <collision>
            <geometry>
                <cylinder length="0.04" radius="0.06" />
            </geometry>
            <origin rpy="1.5707963 0 0" xyz="0 0 0" />
        </collision>
        <inertial>
            <mass value="2" />
            <inertia ixx="0.0020666666666666667" ixy="0" ixz="0" iyy="0.0020666666666666667" iyz="0" izz="0.0036" />
            <origin xyz="0 0 0" rpy="0 0 0" />
        </inertial>
    </link>
    <joint name="left_drive2link" type="continuous">
        <parent link="car_base_link" />
        <child link="left_drive" />
        <origin rpy="0 0 0" xyz="0 0.22 -0.03" />
        <axis xyz="0 1 0" />
    </joint>
    <gazebo reference="left_drive">
        <material>Gazebo/Red</material>
    </gazebo>
    <link name="right_drive">
        <visual>
            <geometry>
                <cylinder length="0.04" radius="0.06" />
            </geometry>
            <origin rpy="1.5707963 0 0" xyz="0 0 0" />
            <material name="wheel_color">
                <color rgba="0 0 0 1" />
            </material>
        </visual>
        <collision>
            <geometry>
                <cylinder length="0.04" radius="0.06" />
            </geometry>
            <origin rpy="1.5707963 0 0" xyz="0 0 0" />
        </collision>
        <inertial>
            <mass value="2" />
            <inertia ixx="0.0020666666666666667" ixy="0" ixz="0" iyy="0.0020666666666666667" iyz="0" izz="0.0036" />
            <origin xyz="0 0 0" rpy="0 0 0" />
        </inertial>
    </link>
    <joint name="right_drive2link" type="continuous">
        <parent link="car_base_link" />
        <child link="right_drive" />
        <origin rpy="0 0 0" xyz="0 -0.22 -0.03" />
        <axis xyz="0 1 0" />
    </joint>
    <gazebo reference="right_drive">
        <material>Gazebo/Red</material>
    </gazebo>
    <link name="left_front_spinner">
        <visual>
            <geometry>
                <sphere radius="0.02" />
            </geometry>
            <origin rpy="0 0 0" xyz="0 0 0" />
            <material name="black">
                <color rgba="0.0 0.0 0.0 1.0" />
            </material>
        </visual>
        <collision>
            <geometry>
                <sphere radius="0.02" />
            </geometry>
            <origin rpy="0 0 0" xyz="0 0 0" />
        </collision>
        <inertial>
            <mass value="0.001" />
            <inertia ixx="1.6e-07" ixy="0" ixz="0" iyy="1.6e-07" iyz="0" izz="1.6e-07" />
            <origin xyz="0 0 0" rpy="0 0 0" />
        </inertial>
    </link>
    <joint name="left_front_spinner2link" type="continuous">
        <parent link="car_base_link" />
        <child link="left_front_spinner" />
        <origin rpy="0 0 0" xyz="0.28 0.16 -0.07" />
        <axis xyz="1 1 1" />
    </joint>
    <gazebo reference="left_front_spinner">
        <material>Gazebo/Red</material>
    </gazebo>
    <link name="right_front_spinner">
        <visual>
            <geometry>
                <sphere radius="0.02" />
            </geometry>
            <origin rpy="0 0 0" xyz="0 0 0" />
            <material name="black">
                <color rgba="0.0 0.0 0.0 1.0" />
            </material>
        </visual>
        <collision>
            <geometry>
                <sphere radius="0.02" />
            </geometry>
            <origin rpy="0 0 0" xyz="0 0 0" />
        </collision>
        <inertial>
            <mass value="0.001" />
            <inertia ixx="1.6e-07" ixy="0" ixz="0" iyy="1.6e-07" iyz="0" izz="1.6e-07" />
            <origin xyz="0 0 0" rpy="0 0 0" />
        </inertial>
    </link>
    <joint name="right_front_spinner2link" type="continuous">
        <parent link="car_base_link" />
        <child link="right_front_spinner" />
        <origin rpy="0 0 0" xyz="0.28 -0.16 -0.07" />
        <axis xyz="1 1 1" />
    </joint>
    <gazebo reference="right_front_spinner">
        <material>Gazebo/Red</material>
    </gazebo>
    <link name="left_back_spinner">
        <visual>
            <geometry>
                <sphere radius="0.02" />
            </geometry>
            <origin rpy="0 0 0" xyz="0 0 0" />
            <material name="black">
                <color rgba="0.0 0.0 0.0 1.0" />
            </material>
        </visual>
        <collision>
            <geometry>
                <sphere radius="0.02" />
            </geometry>
            <origin rpy="0 0 0" xyz="0 0 0" />
        </collision>
        <inertial>
            <mass value="0.001" />
            <inertia ixx="1.6e-07" ixy="0" ixz="0" iyy="1.6e-07" iyz="0" izz="1.6e-07" />
            <origin xyz="0 0 0" rpy="0 0 0" />
        </inertial>
    </link>
    <joint name="left_back_spinner2link" type="continuous">
        <parent link="car_base_link" />
        <child link="left_back_spinner" />
        <origin rpy="0 0 0" xyz="-0.28 0.16 -0.07" />
        <axis xyz="1 1 1" />
    </joint>
    <gazebo reference="left_back_spinner">
        <material>Gazebo/Red</material>
    </gazebo>
    <link name="right_back_spinner">
        <visual>
            <geometry>
                <sphere radius="0.02" />
            </geometry>
            <origin rpy="0 0 0" xyz="0 0 0" />
            <material name="black">
                <color rgba="0.0 0.0 0.0 1.0" />
            </material>
        </visual>
        <collision>
            <geometry>
                <sphere radius="0.02" />
            </geometry>
            <origin rpy="0 0 0" xyz="0 0 0" />
        </collision>
        <inertial>
            <mass value="0.001" />
            <inertia ixx="1.6e-07" ixy="0" ixz="0" iyy="1.6e-07" iyz="0" izz="1.6e-07" />
            <origin xyz="0 0 0" rpy="0 0 0" />
        </inertial>
    </link>
    <joint name="right_back_spinner2link" type="continuous">
        <parent link="car_base_link" />
        <child link="right_back_spinner" />
        <origin rpy="0 0 0" xyz="-0.28 -0.16 -0.07" />
        <axis xyz="1 1 1" />
    </joint>
    <gazebo reference="right_back_spinner">
        <material>Gazebo/Red</material>
    </gazebo>
    <!-- <xacro:include filename="car_info.xacro" /> -->
    <!-- 雷达支架 -->
    <link name="sup">
        <visual>
            <geometry>
                <cylinder length="0.06" radius="0.01" />
            </geometry>
            <origin rpy="0.0 0.0 0.0" xyz="0.0 0.0 0.0" />
            <material name="red">
                <color rgba="0.8 0.2 0.0 0.8" />
            </material>
        </visual>
        <collision>
            <geometry>
                <cylinder length="0.06" radius="0.01" />
            </geometry>
            <origin rpy="0.0 0.0 0.0" xyz="0.0 0.0 0.0" />
        </collision>
        <inertial>
            <mass value="0.02" />
            <inertia ixx="6.5e-06" ixy="0" ixz="0" iyy="6.5e-06" iyz="0" izz="1.0000000000000002e-06" />
            <origin xyz="0 0 0" rpy="0 0 0" />
        </inertial>
    </link>
    <joint name="sup2base_link" type="fixed">
        <parent link="car_base_link" />
        <child link="sup" />
        <origin xyz="0.2 0.0 0.08" />
    </joint>
    <link name="laser">
        <visual>
            <geometry>
                <cylinder length="0.05" radius="0.03" />
            </geometry>
            <origin rpy="0.0 0.0 0.0" xyz="0.0 0.0 0.0" />
            <material name="black" />
        </visual>
        <collision>
            <geometry>
                <cylinder length="0.05" radius="0.03" />
            </geometry>
            <origin rpy="0.0 0.0 0.0" xyz="0.0 0.0 0.0" />
        </collision>
        <inertial>
            <mass value="0.05" />
            <inertia ixx="2.1666666666666664e-05" ixy="0" ixz="0" iyy="2.1666666666666664e-05" iyz="0" izz="2.2499999999999998e-05" />
            <origin xyz="0 0 0" rpy="0 0 0" />
        </inertial>
    </link>
    <joint name="laser2sup" type="fixed">
        <parent link="sup" />
        <child link="laser" />
        <origin xyz="0.0 0.0 0.055" />
    </joint>
    <gazebo reference="sup">
        <material>Gazebo/White</material>
    </gazebo>
    <gazebo reference="laser">
        <material>Gazebo/Black</material>
    </gazebo>
    <!-- Transmission is important to link the joints and the controller -->
    <transmission name="left_drive2link_trans">
        <type>transmission_interface/SimpleTransmission</type>
        <joint name="left_drive2link">
            <!-- <hardwareInterface>hardware_interface/VelocityJointInterface</hardwareInterface> -->
            <hardwareInterface>hardware_interface/PositionJointInterface</hardwareInterface>
        </joint>
        <actuator name="left_drive2link_motor">
            <!-- <hardwareInterface>hardware_interface/VelocityJointInterface</hardwareInterface> -->
            <hardwareInterface>hardware_interface/PositionJointInterface</hardwareInterface>
            <mechanicalReduction>1</mechanicalReduction>
        </actuator>
    </transmission>
    <!-- Transmission is important to link the joints and the controller -->
    <transmission name="right_drive2link_trans">
        <type>transmission_interface/SimpleTransmission</type>
        <joint name="right_drive2link">
            <!-- <hardwareInterface>hardware_interface/VelocityJointInterface</hardwareInterface> -->
            <hardwareInterface>hardware_interface/PositionJointInterface</hardwareInterface>
        </joint>
        <actuator name="right_drive2link_motor">
            <!-- <hardwareInterface>hardware_interface/VelocityJointInterface</hardwareInterface> -->
            <hardwareInterface>hardware_interface/PositionJointInterface</hardwareInterface>
            <mechanicalReduction>1</mechanicalReduction>
        </actuator>
    </transmission>
    <gazebo>
        <plugin filename="libgazebo_ros_diff_drive.so" name="differential_drive_controller">
            <rosDebugLevel>Debug</rosDebugLevel>
            <publishWheelTF>true</publishWheelTF>
            <robotNamespace>/</robotNamespace>
            <publishTf>1</publishTf>
            <publishWheelJointState>true</publishWheelJointState>
            <alwaysOn>true</alwaysOn>
            <updateRate>100</updateRate>
            <legacyMode>true</legacyMode>
            <leftJoint>left_drive2link</leftJoint>
            <!-- 左轮 -->
            <rightJoint>right_drive2link</rightJoint>
            <!-- 右轮 -->
            <wheelSeparation>0.4</wheelSeparation>
            <!-- 车轮间距 -->
            <wheelDiameter>0.12</wheelDiameter>
            <!-- 车轮直径 -->
            <broadcastTF>1</broadcastTF>
            <wheelTorque>30</wheelTorque>
            <wheelAcceleration>1.8</wheelAcceleration>
            <commandTopic>cmd_vel</commandTopic>
            <!-- 运动控制话题 -->
            <odometryFrame>odom</odometryFrame>
            <odometryTopic>odom</odometryTopic>
            <!-- 里程计话题 -->
            <robotBaseFrame>base_footprint</robotBaseFrame>
            <!-- 根坐标系 -->
        </plugin>
    </gazebo>
    <!-- 雷达 -->
    <gazebo reference="laser">
        <sensor name="rplidar" type="ray">
            <pose>0 0 0 0 0 0</pose>
            <visualize>false</visualize>
            <update_rate>60</update_rate>
            <ray>
                <scan>
                    <horizontal>
                        <samples>720</samples>
                        <resolution>1</resolution>
                        <min_angle>-2.2</min_angle>
                        <max_angle>2.2</max_angle>
                    </horizontal>
                </scan>
                <range>
                    <min>0.2</min>
                    <max>20.0</max>
                    <resolution>0.01</resolution>
                </range>
                <noise>
                    <type>gaussian</type>
                    <mean>0.0</mean>
                    <stddev>0.01</stddev>
                </noise>
            </ray>
            <plugin filename="libgazebo_ros_laser.so" name="gazebo_rplidar">
                <topicName>/scan</topicName>
                <frameName>laser</frameName>
            </plugin>
        </sensor>
    </gazebo>
    <link name="dummy_link" />
    <link name="cr5_base_link">
        <inertial>
            <origin rpy="0 0 0" xyz="-8.0961E-06 0.0019103 0.028995" />
            <mass value="0.1" />
            <inertia ixx="0.0014545" ixy="4.2968E-08" ixz="-1.8199E-07" iyy="0.001345" iyz="-6.243E-06" izz="0.002155" />
        </inertial>
        <visual>
            <origin rpy="0 0 0" xyz="0 0 0" />
            <geometry>
                <mesh filename="package://cr5_description/meshes/cr5/base_link.dae" />
            </geometry>
            <material name="">
                <color rgba="0 0 0 1" />
            </material>
        </visual>
        <collision>
            <origin rpy="0 0 0" xyz="0 0 0" />
            <geometry>
                <mesh filename="package://cr5_description/meshes/cr5/base_link.dae" />
            </geometry>
        </collision>
    </link>
    <joint name="dummy_joint" type="fixed">
        <parent link="dummy_link" />
        <child link="cr5_base_link" />
    </joint>
    <link name="Link1">
        <inertial>
            <origin rpy="0 0 0" xyz="-8.7268E-07 -0.0032576 -0.0076748" />
            <mass value="0.1" />
            <inertia ixx="0.0029122" ixy="5.7387E-09" ixz="1.9945E-08" iyy="0.0028191" iyz="0.00044094" izz="0.0032836" />
        </inertial>
        <visual>
            <origin rpy="0 0 0" xyz="0 0 0" />
            <geometry>
                <mesh filename="package://cr5_description/meshes/cr5/Link1.dae" />
            </geometry>
            <material name="">
                <color rgba="1 1 1 1" />
            </material>
        </visual>
        <collision>
            <origin rpy="0 0 0" xyz="0 0 0" />
            <geometry>
                <mesh filename="package://cr5_description/meshes/cr5/Link1.dae" />
            </geometry>
        </collision>
    </link>
    <joint name="joint1" type="revolute">
        <origin rpy="0 0 0" xyz="0 0 0.147" />
        <parent link="cr5_base_link" />
        <child link="Link1" />
        <axis xyz="0 0 1" />
        <limit effort="300" lower="-3.14" upper="3.14" velocity="100" />
    </joint>
    <link name="Link2">
        <inertial>
            <origin rpy="0 0 0" xyz="-0.21351 -1.3842E-06 0.14252" />
            <mass value="0.1" />
            <inertia ixx="0.0085919" ixy="7.5552E-07" ixz="-7.8922E-07" iyy="0.027553" iyz="1.4629E-07" izz="0.028294" />
        </inertial>
        <visual>
            <origin rpy="0 0 0" xyz="0 0 0" />
            <geometry>
                <mesh filename="package://cr5_description/meshes/cr5/Link2.dae" />
            </geometry>
            <material name="">
                <color rgba="1 1 1 1" />
            </material>
        </visual>
        <collision>
            <origin rpy="0 0 0" xyz="0 0 0" />
            <geometry>
                <mesh filename="package://cr5_description/meshes/cr5/Link2.dae" />
            </geometry>
        </collision>
    </link>
    <joint name="joint2" type="revolute">
        <origin rpy="1.5708 1.5708 0" xyz="0 0 0" />
        <parent link="Link1" />
        <child link="Link2" />
        <axis xyz="0 0 1" />
        <limit effort="300" lower="-2" upper="1.25" velocity="100" />
    </joint>
    <link name="Link3">
        <inertial>
            <origin rpy="0 0 0" xyz="-0.15231 -1.4079E-07 0.022693" />
            <mass value="0.1" />
            <inertia ixx="0.0032608" ixy="-3.2147E-10" ixz="0.00012363" iyy="0.0092967" iyz="2.9478E-10" izz="0.0095552" />
        </inertial>
        <visual>
            <origin rpy="0 0 0" xyz="0 0 0" />
            <geometry>
                <mesh filename="package://cr5_description/meshes/cr5/Link3.dae" />
            </geometry>
            <material name="">
                <color rgba="1 1 1 1" />
            </material>
        </visual>
        <collision>
            <origin rpy="0 0 0" xyz="0 0 0" />
            <geometry>
                <mesh filename="package://cr5_description/meshes/cr5/Link3.dae" />
            </geometry>
        </collision>
    </link>
    <joint name="joint3" type="revolute">
        <origin rpy="0 0 0" xyz="-0.427 0 0" />
        <parent link="Link2" />
        <child link="Link3" />
        <axis xyz="0 0 1" />
        <limit effort="300" lower="-2.5" upper="2.5" velocity="100" />
    </joint>
    <link name="Link4">
        <inertial>
            <origin rpy="0 0 0" xyz="-3.2386E-07 -0.002077 -0.0015548" />
            <mass value="0.1" />
            <inertia ixx="0.00066939" ixy="4.1975E-10" ixz="-1.0734E-08" iyy="0.00065424" iyz="0.00011081" izz="0.00065365" />
        </inertial>
        <visual>
            <origin rpy="0 0 0" xyz="0 0 0" />
            <geometry>
                <mesh filename="package://cr5_description/meshes/cr5/Link4.dae" />
            </geometry>
            <material name="">
                <color rgba="1 1 1 1" />
            </material>
        </visual>
        <collision>
            <origin rpy="0 0 0" xyz="0 0 0" />
            <geometry>
                <mesh filename="package://cr5_description/meshes/cr5/Link4.dae" />
            </geometry>
        </collision>
    </link>
    <joint name="joint4" type="revolute">
        <origin rpy="0 0 -1.5708" xyz="-0.357 0 0.141" />
        <parent link="Link3" />
        <child link="Link4" />
        <axis xyz="0 0 1" />
        <limit effort="300" lower="-3.14" upper="3.14" velocity="100" />
    </joint>
    <link name="Link5">
        <inertial>
            <origin rpy="0 0 0" xyz="-3.7738E-07 -0.0045777 -0.0012971" />
            <mass value="0.1" />
            <inertia ixx="0.00073069" ixy="-5.7806E-09" ixz="6.7132E-09" iyy="0.00071195" iyz="-0.00011926" izz="0.00071391" />
        </inertial>
        <visual>
            <origin rpy="0 0 0" xyz="0 0 0" />
            <geometry>
                <mesh filename="package://cr5_description/meshes/cr5/Link5.dae" />
            </geometry>
            <material name="">
                <color rgba="1 1 1 1" />
            </material>
        </visual>
        <collision>
            <origin rpy="0 0 0" xyz="0 0 0" />
            <geometry>
                <mesh filename="package://cr5_description/meshes/cr5/Link5.dae" />
            </geometry>
        </collision>
    </link>
    <joint name="joint5" type="revolute">
        <origin rpy="1.5708 0 0" xyz="0 -0.116 0" />
        <parent link="Link4" />
        <child link="Link5" />
        <axis xyz="0 0 1" />
        <limit effort="300" lower="-3.14" upper="3.14" velocity="100" />
    </joint>
    <link name="Link6">
        <inertial>
            <origin rpy="0 0 0" xyz="5.0777E-11 9.3774E-05 -0.019285" />
            <mass value="0.1" />
            <inertia ixx="7.8045E-05" ixy="6.1582E-15" ixz="6.2471E-14" iyy="7.9168E-05" iyz="-1.3822E-07" izz="0.00012951" />
        </inertial>
        <visual>
            <origin rpy="0 0 0" xyz="0 0 0" />
            <geometry>
                <mesh filename="package://cr5_description/meshes/cr5/Link6.dae" />
            </geometry>
            <material name="">
                <color rgba="1 1 1 1" />
            </material>
        </visual>
        <collision>
            <origin rpy="0 0 0" xyz="0 0 0" />
            <geometry>
                <mesh filename="package://cr5_description/meshes/cr5/Link6.dae" />
            </geometry>
        </collision>
    </link>
    <joint name="joint6" type="revolute">
        <origin rpy="-1.5708 0 0" xyz="0 0.105 0" />
        <parent link="Link5" />
        <child link="Link6" />
        <axis xyz="0 0 1" />
        <limit effort="300" lower="-6.28" upper="6.28" velocity="100" />
    </joint>
    <!-- Grasping frame -->
    <link name="grasping_frame" />
    <joint name="grasping_frame_joint" type="fixed">
        <parent link="Link6" />
        <child link="grasping_frame" />
        <origin rpy="0 0 0" xyz="0 0 0.115" />
    </joint>
    <link name="gripper_base_link">
        <inertial>
            <origin rpy="0 0 0" xyz="-3.9257E-06 -0.00027208 0.037806" />
            <mass value="0.34365" />
            <inertia ixx="0.00036805" ixy="-7.2868E-08" ixz="-5.0168E-08" iyy="0.0003341" iyz="-2.6462E-06" izz="0.00022294" />
        </inertial>
        <visual>
            <origin rpy="0 0 0" xyz="0 0 0" />
            <geometry>
                <mesh filename="package://cr5_description/meshes/gripper_base_link.STL" />
            </geometry>
            <material name="">
                <color rgba="1 1 1 1" />
            </material>
        </visual>
        <collision>
            <origin rpy="0 0 0" xyz="0 0 0" />
            <geometry>
                <mesh filename="package://cr5_description/meshes/gripper_base_link.STL" />
            </geometry>
        </collision>
    </link>
    <link name="finger1_link">
        <inertial>
            <origin rpy="0 0 0" xyz="0.0030491 -0.0066024 0.0064209" />
            <mass value="0.014278" />
            <inertia ixx="1.7567E-06" ixy="-5.7832E-08" ixz="2.6803E-08" iyy="2.3034E-06" iyz="2.2145E-07" izz="1.3354E-06" />
        </inertial>
        <visual>
            <origin rpy="0 0 0" xyz="0 0 0" />
            <geometry>
                <mesh filename="package://cr5_description/meshes/finger1_Link.STL" />
            </geometry>
            <material name="">
                <color rgba="1 1 1 1" />
            </material>
        </visual>
        <collision>
            <origin rpy="0 0 0" xyz="0 0 0" />
            <geometry>
                <mesh filename="package://cr5_description/meshes/finger1_Link.STL" />
            </geometry>
        </collision>
    </link>
    <joint name="finger1_joint" type="prismatic">
        <origin rpy="0 0 -1.5708" xyz="0.0132 0.0265 0.093" />
        <parent link="gripper_base_link" />
        <child link="finger1_link" />
        <axis xyz="1 0 0" />
        <limit effort="300" lower="0" upper="0.025" velocity="100" />
    </joint>
    <link name="finger2_link">
        <inertial>
            <origin rpy="0 0 0" xyz="0.0030491 -0.0066024 0.0064209" />
            <mass value="0.014278" />
            <inertia ixx="1.7567E-06" ixy="-5.7832E-08" ixz="2.6803E-08" iyy="2.3034E-06" iyz="2.2145E-07" izz="1.3354E-06" />
        </inertial>
        <visual>
            <origin rpy="0 0 0" xyz="0 0 0" />
            <geometry>
                <mesh filename="package://cr5_description/meshes/finger2_Link.STL" />
            </geometry>
            <material name="">
                <color rgba="0.79216 0.81961 0.93333 1" />
            </material>
        </visual>
        <collision>
            <origin rpy="0 0 0" xyz="0 0 0" />
            <geometry>
                <mesh filename="package://cr5_description/meshes/finger2_Link.STL" />
            </geometry>
        </collision>
    </link>
    <joint name="finger2_joint" type="prismatic">
        <origin rpy="0 0 1.5708" xyz="-0.0132 -0.0265 0.093" />
        <parent link="gripper_base_link" />
        <child link="finger2_link" />
        <axis xyz="1 0 0" />
        <limit effort="300" lower="0" upper="0.025" velocity="100" />
    </joint>
    <joint name="gripper2cr5" type="fixed">
        <parent link="Link6" />
        <child link="gripper_base_link" />
        <origin rpy="0 0 0" xyz="0 0 0" />
    </joint>
    <transmission name="tran1">
        <type>transmission_interface/SimpleTransmission</type>
        <joint name="joint1">
            <hardwareInterface>hardware_interface/PositionJointInterface</hardwareInterface>
        </joint>
        <actuator name="motor1">
            <hardwareInterface>hardware_interface/PositionJointInterface</hardwareInterface>
            <mechanicalReduction>1</mechanicalReduction>
        </actuator>
    </transmission>
    <transmission name="tran1">
        <type>transmission_interface/SimpleTransmission</type>
        <joint name="joint2">
            <hardwareInterface>hardware_interface/PositionJointInterface</hardwareInterface>
        </joint>
        <actuator name="motor1">
            <hardwareInterface>hardware_interface/PositionJointInterface</hardwareInterface>
            <mechanicalReduction>1</mechanicalReduction>
        </actuator>
    </transmission>
    <transmission name="tran1">
        <type>transmission_interface/SimpleTransmission</type>
        <joint name="joint3">
            <hardwareInterface>hardware_interface/PositionJointInterface</hardwareInterface>
        </joint>
        <actuator name="motor1">
            <hardwareInterface>hardware_interface/PositionJointInterface</hardwareInterface>
            <mechanicalReduction>1</mechanicalReduction>
        </actuator>
    </transmission>
    <transmission name="tran1">
        <type>transmission_interface/SimpleTransmission</type>
        <joint name="joint4">
            <hardwareInterface>hardware_interface/PositionJointInterface</hardwareInterface>
        </joint>
        <actuator name="motor1">
            <hardwareInterface>hardware_interface/PositionJointInterface</hardwareInterface>
            <mechanicalReduction>1</mechanicalReduction>
        </actuator>
    </transmission>
    <transmission name="tran1">
        <type>transmission_interface/SimpleTransmission</type>
        <joint name="joint5">
            <hardwareInterface>hardware_interface/PositionJointInterface</hardwareInterface>
        </joint>
        <actuator name="motor1">
            <hardwareInterface>hardware_interface/PositionJointInterface</hardwareInterface>
            <mechanicalReduction>1</mechanicalReduction>
        </actuator>
    </transmission>
    <transmission name="tran1">
        <type>transmission_interface/SimpleTransmission</type>
        <joint name="joint6">
            <hardwareInterface>hardware_interface/PositionJointInterface</hardwareInterface>
        </joint>
        <actuator name="motor1">
            <hardwareInterface>hardware_interface/PositionJointInterface</hardwareInterface>
            <mechanicalReduction>1</mechanicalReduction>
        </actuator>
    </transmission>
    <transmission name="tran1">
        <type>transmission_interface/SimpleTransmission</type>
        <joint name="finger1_joint">
            <hardwareInterface>hardware_interface/PositionJointInterface</hardwareInterface>
        </joint>
        <actuator name="motor1">
            <hardwareInterface>hardware_interface/PositionJointInterface</hardwareInterface>
            <mechanicalReduction>1</mechanicalReduction>
        </actuator>
    </transmission>
    <transmission name="tran1">
        <type>transmission_interface/SimpleTransmission</type>
        <joint name="finger2_joint">
            <hardwareInterface>hardware_interface/PositionJointInterface</hardwareInterface>
        </joint>
        <actuator name="motor1">
            <hardwareInterface>hardware_interface/PositionJointInterface</hardwareInterface>
            <mechanicalReduction>1</mechanicalReduction>
        </actuator>
    </transmission>
    <gazebo>
        <plugin filename="libgazebo_ros_control.so" name="gazebo_ros_control">
            <robotNamespace>/</robotNamespace>
        </plugin>
    </gazebo>
    <gazebo>
        <plugin filename="libgazebo_grasp_fix.so" name="gazebo_grasp_fix">
            <arm>
                <arm_name>dh_pgc140_urdf</arm_name>
                <palm_link>Link6</palm_link>
                <gripper_link>finger1_link</gripper_link>
                <gripper_link>finger2_link</gripper_link>
                <!-- <gripper_link> ... </gripper_link> -->
            </arm>
            <forces_angle_tolerance>100</forces_angle_tolerance>
            <update_rate>4</update_rate>
            <grip_count_threshold>4</grip_count_threshold>
            <max_grip_count>8</max_grip_count>
            <release_tolerance>0.005</release_tolerance>
            <disable_collisions_on_attach>false</disable_collisions_on_attach>
            <contact_topic>__default_topic__</contact_topic>
        </plugin>
    </gazebo>
    <gazebo reference="Link1">
        <selfCollide>true</selfCollide>
    </gazebo>
    <gazebo reference="Link2">
        <selfCollide>true</selfCollide>
    </gazebo>
    <gazebo reference="Link3">
        <selfCollide>true</selfCollide>
    </gazebo>
    <gazebo reference="Link4">
        <selfCollide>true</selfCollide>
    </gazebo>
    <gazebo reference="Link5">
        <selfCollide>true</selfCollide>
    </gazebo>
    <gazebo reference="Link6">
        <selfCollide>true</selfCollide>
    </gazebo>
    <gazebo reference="gripper_base_link">
        <selfCollide>true</selfCollide>
    </gazebo>
    <gazebo reference="finger1_link">
        <selfCollide>true</selfCollide>
    </gazebo>
    <gazebo reference="finger2_link">
        <selfCollide>true</selfCollide>
    </gazebo>
    <joint name="arm2car" type="fixed">
        <parent link="car_base_link" />
        <child link="dummy_link" />
        <origin rpy="0 0 0" xyz="0 0 0.07" />
        <axis xyz="0.0 0.0 0.0" />
        <limit effort="0.0" lower="0.0" upper="0.0" velocity="0.0" />
    </joint>
    <transmission name="trans_left_front_spinner2link">
        <type>transmission_interface/SimpleTransmission</type>
        <joint name="left_front_spinner2link">
            <hardwareInterface>hardware_interface/EffortJointInterface</hardwareInterface>
        </joint>
        <actuator name="left_front_spinner2link_motor">
            <hardwareInterface>hardware_interface/EffortJointInterface</hardwareInterface>
            <mechanicalReduction>1</mechanicalReduction>
        </actuator>
    </transmission>
    <transmission name="trans_right_front_spinner2link">
        <type>transmission_interface/SimpleTransmission</type>
        <joint name="right_front_spinner2link">
            <hardwareInterface>hardware_interface/EffortJointInterface</hardwareInterface>
        </joint>
        <actuator name="right_front_spinner2link_motor">
            <hardwareInterface>hardware_interface/EffortJointInterface</hardwareInterface>
            <mechanicalReduction>1</mechanicalReduction>
        </actuator>
    </transmission>
    <transmission name="trans_left_back_spinner2link">
        <type>transmission_interface/SimpleTransmission</type>
        <joint name="left_back_spinner2link">
            <hardwareInterface>hardware_interface/EffortJointInterface</hardwareInterface>
        </joint>
        <actuator name="left_back_spinner2link_motor">
            <hardwareInterface>hardware_interface/EffortJointInterface</hardwareInterface>
            <mechanicalReduction>1</mechanicalReduction>
        </actuator>
    </transmission>
    <transmission name="trans_right_back_spinner2link">
        <type>transmission_interface/SimpleTransmission</type>
        <joint name="right_back_spinner2link">
            <hardwareInterface>hardware_interface/EffortJointInterface</hardwareInterface>
        </joint>
        <actuator name="right_back_spinner2link_motor">
            <hardwareInterface>hardware_interface/EffortJointInterface</hardwareInterface>
            <mechanicalReduction>1</mechanicalReduction>
        </actuator>
    </transmission>
</robot>

